1. try/catch 捕获的是同步错误
2. Promise 抛出错误，并不会阻止运行时继续执行同步任务

```js
try {
  let aaa = "abc";
  var abc = "abc";
  console.log(132);
  // throw "hh";
  console.log(321);
} catch (error) {
  console.log(error, "error");
  console.log(aaa);
}
console.log(abc);
```

```js
const promiseFun = (bole = true) => {
  return new Promise((resolve, reject) => {
    console.log("promise");
    throw "hh";
    if (bole) {
      resolve("resolve___");
    } else {
      reject("reject___");
    }
  });
};

const myFun = async function () {
  try {
    promiseFun().then(() => {
      console.log("then");
    });
    // throw "hh";
    console.log(321);
  } catch (error) {
    console.log(error, "error");
  }
};

myFun();
```

1. try 中{}作用域同样的，在{}外无法访问 let const 声明的变量
2. try catch 中抛出异常，不会阻塞 try catch 外的同步代码执行，但 try 中 throw 后的代码会被阻塞
3. try catch 无法捕获 promise 中的 throw，一旦 throw，promise 中的后续代码不会执行，但 promiseFun 后的代码仍可运行

```js
await promiseFun().then(() => {
  console.log("then");
});
```

1. 使用 await 后，try catch 可以捕获到 promise 中的错误

```js
const myFun = async function () {
  try {
    await promiseFun(false).then(() => {
      console.log("then");
    });
    // throw "hh";
    // console.log(bb);
  } catch (error) {
    console.log(error, "error");
  }
};
```

1. 使用 await 后，promise reject 时，try catch 可以捕获到错误

```js
const myFun = async function () {
  try {
    await promiseFun().then(async () => {
      console.log("then");
      await promiseFun(false).then(() => {
        console.log("catch");
      });
    });
    // throw "hh";
    // console.log(bb);
  } catch (error) {
    console.log(error, "error");
  }
};
```

1. 使用 await 后，promise 嵌套多层仍有效捕获

```js
const myFun = async function () {
  try {
    await promiseFun().then(async () => {
      console.log("then");
      await promiseFun(false)
        .then(() => {
          console.log("catch");
        })
        .catch(() => {
          // throw "hh";
          console.log("catch2");
        });
    });
    // throw "hh";
    // console.log(bb);
  } catch (error) {
    console.log(error, "error");
  }
};
```

1. 一旦通过 promise 的.catch 进行捕获后，错误 就不会给到 try catch
2. 但可以再 promise 的.catch 中 通过 throw 暴露给到 try catch 捕获 throw 的错误

```js
const nFun = async function () {
  try {
    await promiseFun(false).then(async () => {
      console.log("then222");
    });
  } catch (error) {
    console.log(error, "error222");
  }
};

const myFun = async function () {
  try {
    await promiseFun().then(async () => {
      console.log("then");
      try {
        await promiseFun().then(() => {
          console.log("catch");
          nFun();
        });
      } catch (error) {
        console.log(error, "error2");
      }
    });
  } catch (error) {
    console.log(error, "error");
  }
};
```

1. 自然的，以上也是只要最近的 try catch 捕获到，并且不继续往外报错误，不影响后续代码

总结：
异常只要捕获，都不影响后续逻辑代码执行

try catch 只能捕获同步代码的异常

promise catch 可以捕获到 promise 内部的 throw 以及 reject
